Workbook

Sheet Pre-planning & Programming
A1: PRE-PLANNING/PROGRAMMING TOOL
B2: Pre-Planning/Programming Worksheet
C3: The items listed in below will help the team determine whether and to what extent MBH friendly design considerations should be incorporated in the proposed project
B4: Consideration | D4: Response (Select one from the drop down list) | E4: Response (Open-ended)
B6: 1 | C6: What is the strategic vision for the hospital/health system?
B7: =B6+1 -> 2 | C7: What are the main drivers/motivators for the ED redesign (for renovation)/ design (new construction) project?
B8: =B7+1 -> 3 | C8: Is this project a renovation or new construction?
B9: =B8+1 -> 4 | C9: Does the ED serve pediatric patients, adult patients, or both?
B10: =B9+1 -> 5 | C10: What is the anticipated total annual patient volume for this ED?
B11: =B10+1 -> 6 | C11: What is the anticipated total annual mental and behavioral health patient volume for this ED?
B12: =B11+1 -> 7 | C12: Will the ED serve any prisoners/penitentiary patients?
B13: =B12+1 -> 8 | C13: What is the anticipated proportion of uninsured patients in the ED?
B14: =B13+1 -> 9 | C14: Approximately what percentage of patients that will be seen in this ED (for all visit reasons) are:
C15: a. Children under age 5
C16: b. Children aged 5-12
C17: c. Adolescents aged 13-18
C18: d. Young Adults aged 18-24
C19: e. Adults aged 25-65
C20: f. Adults over age 65
B21: =B14+1 -> 10 | C21: Based on the ED's annual patient data (last 5 years), please share the annual patient volumes for each these categories.
C22: i. Suicidal Behavior & Risk
C23: a. Children under age 5
C24: b. Children aged 5-12
C25: c. Adolescents aged 13-18
C26: d. Young Adults aged 18-24
C27: e. Adults aged 25-65
C28: f. Adults over age 65
C29: ii. Aggressive Behaviors
C30: a. Children under age 5
C31: b. Children aged 5-12
C32: c. Adolescents aged 13-18
C33: d. Young Adults aged 18-24
... C49: f. Adults over age 65
B50: =B21+1 -> 11 | C50: Based on the ED's annual patient data (last 5 years), please share the weekly patient volumes for each these categories.
C51: i. MBH Conditions
C52: a. Children aged 0-12
C53: b. Adolescents aged 13-18
C54: c. Adults aged over 18
C55: ii. Medical Conditions
C56: a. Children aged 0-12
...

Sheet Outcome Priotization
B2: OUTCOME-GUIDELINE PRIORITIZATION TOOL
C5: Design Objectives Worksheet
C6: Review the importance of each design outcomes and metrics, then select from the options in the dropdown menu in the "Importance" column.
C7: Your revision will determine priotization of the design objectives
C10: Design Objectives | D10: Design Outcomes/metrics | E10: Description | F10: Importance | I10: Outcomes | J10: Values | K10: Objectives priotization | L10: Priority Order
C12: Improve Safety & Security | D12: Preventing Self Harm | E12: Preventing self-harm involves implementing strategies to identify at-risk individuals, provide timely support, and reduce factors that contribute to self-injurious behaviors. | F12: Critically Important / Essential | I12: Improve Safety & Security | J12: {=AVERAGE(IFERROR(VLOOKUP(F12:F20,'Response Options'!D5:E10,2,FALSE),0))} -> 4 | K12: {=_xlfn.SORTBY(I12:I17,J12:J17,-1)} -> Improve Safety & Security | L12: First priority
D13: Preveting Elopement | E13: Preventing elopement involves implementing strategies and interventions to reduce the risk of individuals from leaving a safe environment without supervision. | F13: Moderately Important | I13: Optimize Efficiency & Effectiveness | J13: {=AVERAGE(IFERROR(VLOOKUP(F21:F25,'Response Options'!D5:E10,2,FALSE),0))} -> 3.4 | K13: Provide Patient Choice and Control | L13: Second priority
D14: Quicker response in emergency events | E14: Ensure rapid identification and intervention in emergencies and (self) harm incidents to minimize risk, providing immediate support from healthcare staff. | F14: Critically Important / Essential | I14: Improve Communication | J14: {=AVERAGE(IFERROR(VLOOKUP(F26:F30,'Response Options'!D5:E10,2,FALSE),0))} -> 1.8 | K14: Improve Overall Comfort for All Users | L14: Third priority
D15: Perception of safety | E15: Perception of Safety refers to individuals’ feelings and beliefs about how safe they are in a given environment. | F15: Slightly important | I15: Improve Overall Comfort for All Users | J15: {=AVERAGE(IFERROR(VLOOKUP(F31:F35,'Response Options'!D5:E10,2,FALSE),0))} -> 3.8 | K15: Optimize Efficiency & Effectiveness | L15: Fourth priority
D16: Quick response to patient-initiated harm | E16: Improve the speed and effectiveness of interventions when patients initiate harm to others or to the environment. | F16: Critically Important / Essential | I16: Improve Patient and Family Agency | J16: {=AVERAGE(IFERROR(VLOOKUP(F36:F39,'Response Options'!D5:E10,2,FALSE),0))} -> 2.25 | K16: Improve Patient and Family Agency | L16: Fifth priority
D17: Reduce patient-initiated harm | E17: Reduce patient-initiated harm aims to minimize incidents where patients cause harm to themselves, staff, or others within the healthcare setting. | F17: Very Important | I17: Provide Patient Choice and Control | J17: {=AVERAGE(IFERROR(VLOOKUP(F40:F42,'Response Options'!D5:E10,2,FALSE),0))} -> 4 | K17: Improve Communication | L17: Sixth priority
D18: Reduce need for restraints | E18: Reduce the frequency and necessity of using physical or chemical restraints. | F18: Critically Important / Essential
D19: Reduce exposure to triggering content | E19: Reduced exposure to triggering content aims to minimize an individual's contact with situations, media or people that may provoke distressing emotions or reactions. | F19: Critically Important / Essential
D20: Enhances patient visibility | E20: Provide visual access to the patient, improving the ability of healthcare providers to access, track, and monitor patient information in real time. | F20: Critically Important / Essential
C21: Optimize Efficiency & Effectiveness | D21: Reduce staff workload (physical and cognitive) | E21: Implement strategies and tools to minimize manual and mental, reducing the overall workload and task demmands for staff. | F21: Extremely Important
D22: Reduce ED waiting times and/or length of stay | E22: Implement targeted process improvements to reduce emergency department waiting times and overall length of stay. | F22: Slightly unimportant
D23: Adequate care for co-occurring med/psych conditions | E23: Ensure that individuals receive appropriate assessment, treatment, and ongoing management for both medical and psychiatric conditions. | F23: Very Important
D24: Improved coordination of patient flow | E24: Streamline the movement of patients through the ED during various stages of care, ensuring timely admissions, transfers, and discharges. | F24: Critically Important / Essential
D25: Provision of appropriate psych care in the ED | E25: Ensure that patients presenting to the ED with MBH concerns receive timely assessment, stabilization, and access to appropriate psychiatric interventions. | F25: Critically Important / Essential
C26: Improve Communication | D26: Enhance team coordination and collaboration | E26: Foster a collaborative environment to ensure team members work effectively together towards shared goals. | F26: Extremely Important
D27: Quick response from medical team | E27: Ensure that the medical care teams provide timely and effective responses to urgent situations and codes. | F27: Moderately Important
D28: Streamlined flow of information | E28: Optimizing communication channels and processes to ensure that relevant data and updates are efficiently shared among care team members. | F28: Slightly unimportant
D29: Support staff and resident training | E29: Provide comprehensive support to allow staff and resident training in the ED | F29: Moderately Important
D30: Reduced miscommunication with family members | E30: Provide clarity of information in interactions with family members, minimizing misunderstandings. | F30: Slightly important
C31: Improve Overall Comfort for All Users | D31: Enhance Patient and family satisfaction | E31: Enhance the satisfaction and emotional well-being of patients and their families by addressing their needs, preferences, and concerns. | F31: Critically Important / Essential
D32: Improve Patient and family comfort | E32: Enhance the physical and physiological well-being of patients and their families. | F32: Very Important
D33: Reduce anxiety | E33: Reduces anxiety by promoting relaxation, calming the mind, and decreasing feelings of worry or nervousness. | F33: Critically Important / Essential
D34: Reduce crowding | E34: Minimize the number of people in a given space at one time, to reduce the discomfort and stress associated with the perception of being crowded | F34: Critically Important / Essential
D35: Enhanced staff satisfaction | E35: Enhanced staff satisfaction focuses on improving the emotional well-being, engagement, and morale of employees | F35: Slightly important
C36: Improve Patient and Family Agency | D36: Facilitating family participation in care | E36: Encourage and support family involvement in the patient’s care and empower to participate in decision-making and care activities. | F36: Moderately Important
D37: Promoting trust and rapport | E37: Establishes a positive, respectful, and empathetic environment to the patient and family members need | F37: Extremely Important
D38: Safeguard patient confidential information | E38: Ensure that all patient information is protected from unauthorized access, disclosure, or misuse by following established privacy policies and practices such as HIPAA. | F38: Very Important
D39: Limits being seen by others | E39: Reduce the likelihood that of patients to be exposed to other patients or the general public after being admitted to ED. | F39: Slightly unimportant
C40: Provide Patient Choice and Control | D40: Reduce agitation & boredom | E40: Reduces agitation and boredom, minimizing restlessness and disruptive behaviors. | F40: Critically Important / Essential
D41: Enhance sense of dignity | E41: Foster an environment where individuals feel respected, valued, and empowered, promoting self-worth and personal pride in all interactions and activities. | F41: Critically Important / Essential
D42: Improve emotional & sleep regulation | E42: Enhance the ability to manage emotions and establish healthy sleep routines while in the ED | F42: Moderately Important

Sheet Policy & Process-based Design
A1: POLICY & PROCESS-BASED DESIGN FRAMEWORK
B2: Stakeholder Engagement & Design Discussion Worksheet
C3: The prompts listed in the process & policy considerations and design implicaitons will help the team determine the design strategies to be considered in the proposed project
B4: Process & Policy Consideration & Design Implications | D4: Response (Open-ended) | E4: Design Implications Questions | F4: Design Response | G4: Relevant Design Elements ** | K4: score | L4: Round | M4: Importance | N4: Relevant Design Objectives/Outcomes
G5: Architectural Elements | H5: Furnishings & Finishes | I5: MEP & Building Systems | J5: Technology & Other Elements | N5: Improve Safety & Security | W5: Optimize Efficiency & Effectiveness | AB5: Improve Communication | AG5: Improve Overall Comfort for All Users | AL5: Improve Patient and Family Agency | AP5: Provide Patient Choice and Control
N6: Preventing Self Harm | O6: Preveting Elopement | P6: Quicker response in emergency events | Q6: Perception of safety | R6: Quick response to patient-initiated harm | S6: Reduce harm aggainst others | T6: Reduce need for restraints | U6: Reduce exposure to triggering content | V6: Enhances patient visibility | W6: Reduce staff workload (physical and cognitive) | X6: Reduce ED waiting times and/or length of stay | Y6: Adequate care for co-occurring med/psych conditions | Z6: Improved coordination of patient flow | AA6: Provision of appropriate psych care in the ED | AB6: Enhance team coordination and collaboration | AC6: Quick response from medical team | AD6: Streamlined flow of information | AE6: Support staff and resident training | AF6: Reduced miscommunication with family members | AG6: Enhance Patient and family satisfaction | AH6: Improve Patient and family comfort | AI6: Reduce anxiety | AJ6: Reduce crowding | AK6: Enhanced staff satisfaction | AL6: Facilitating family participation in care | AM6: Promoting trust and rapport | AN6: Safeguard patient confidential information | AO6: Limits being seen by others | AP6: Reduce agitation & boredom | AQ6: Enhance sense of dignity | AR6: Improve emotional & sleep regulation
C7: Screening
B8: 1 | C8: Security Screening:
B9: 1.1 | C9: How do you anticipate screening all patients/care partners for ligature risks and contraband items before entering the ED? | E9: a. What equipment/system do you anticipate using for screening patients and care partners before entering the ED? | G9: X | H9: X | I9: X | J9: X | K9: {=SUMPRODUCT(IFERROR(VLOOKUP(N9:AR9,'Response Options'!$D$5:$E$10,2,FALSE),0))/COUNTA(N9:AR9)} -> 3 | L9: =ROUND(K9,0) -> 3 | M9: =_xlfn.XLOOKUP(L9,'Response Options'!$E$5:$E$10,'Response Options'!$D$5:$D$10) -> Very Important | N9: ='Outcome Priotization'!F12 -> Critically Important / Essential | Q9: ='Outcome Priotization'!F15 -> Slightly important | S9: ='Outcome Priotization'!F17 -> Very Important
E10: b. Where do you anticipate screening patients and care partners before entering the ED? | G10: X | H10: X | I10: X | J10: X
B11: 2 | C11: Mental & Behavioral Health (MBH) Screening:
B12: 2.1 | C12: How do you anticipate screening patients for aggression and suicide risk upon entering the ED (walk-in & EMS patients)? | E12: a. Do you anticipate having an alternate route for taking aggressive/suicidal patients to the patient room after screening? | G12: X | K12: {=SUMPRODUCT(IFERROR(VLOOKUP(N12:AR12,'Response Options'!$D$5:$E$10,2,FALSE),0))/COUNTA(N12:AR12)} -> 3.8571429 | L12: =ROUND(K12,0) -> 4 | M12: =_xlfn.XLOOKUP(L12,'Response Options'!$E$5:$E$10,'Response Options'!$D$5:$D$10) -> Extremely Important | N12: ='Outcome Priotization'!$F$12 -> Critically Important / Essential | O12: ='Outcome Priotization'!F13 -> Moderately Important | P12: ='Outcome Priotization'!F14 -> Critically Important / Essential | Q12: ='Outcome Priotization'!F15 -> Slightly important | R12: ='Outcome Priotization'!F16 -> Critically Important / Essential | S12: ='Outcome Priotization'!F17 -> Very Important | U12: ='Outcome Priotization'!F19 -> Critically Important / Essential | X12: ='Outcome Priotization'!F22 -> Slightly unimportant | Y12: ='Outcome Priotization'!F23 -> Very Important | Z12: ='Outcome Priotization'!F24 -> Critically Important / Essential | AA12: ='Outcome Priotization'!F25 -> Critically Important / Essential | AI12: ='Outcome Priotization'!F33 -> Critically Important / Essential | AJ12: ='Outcome Priotization'!F34 -> Critically Important / Essential | AP12: ='Outcome Priotization'!F40 -> Critically Important / Essential
B13: 2.2 | C13: Do you anticipate MBH patients and their care partners waiting in the Waiting Area | E13: a. Where do you anticipate the MBH patients will wait in the ED? | G13: X | H13: X | I13: X | J13: X | K13: {=SUMPRODUCT(IFERROR(VLOOKUP(N13:AR13,'Response Options'!$D$5:$E$10,2,FALSE),0))/COUNTA(N13:AR13)} -> 3.3846154 | L13: =ROUND(K13,0) -> 3 | M13: =_xlfn.XLOOKUP(L13,'Response Options'!$E$5:$E$10,'Response Options'!$D$5:$D$10) -> Very Important | N13: ='Outcome Priotization'!$F$12 -> Critically Important / Essential | O13: ='Outcome Priotization'!F13 -> Moderately Important | Q13: ='Outcome Priotization'!F15 -> Slightly important | U13: ='Outcome Priotization'!F19 -> Critically Important / Essential | X13: ='Outcome Priotization'!F22 -> Slightly unimportant | Y13: ='Outcome Priotization'!F23 -> Very Important | Z13: ='Outcome Priotization'!F24 -> Critically Important / Essential | AA13: ='Outcome Priotization'!F25 -> Critically Important / Essential | AH13: ='Outcome Priotization'!F32 -> Very Important | AI13: ='Outcome Priotization'!F33 -> Critically Important / Essential | AJ13: ='Outcome Priotization'!F34 -> Critically Important / Essential | AO13: ='Outcome Priotization'!F39 -> Slightly unimportant | AP13: ='Outcome Priotization'!F40 -> Critically Important / Essential
E14: b. How do you anticipate minimizing ligature risks in the MBH waiting space? | G14: X | H14: X | I14: X | J14: X
E15: c. How do you anticipate minimizing elopement risks in the MBH waiting space? | G15: X | H15: X | I15: X | J15: X
E16: d. How do you anticipate engaging/distracting MBH patients and their care partners in the ED waiting area? | G16: X | H16: X | I16: X | J16: X
C17: Triaging & Initial Assessment
B18: 3 | C18: Triaging:
B19: 3.1 | C19: How do you anticipate triaging MBH patients in the ED? | E19: a. Where do you anticipate triaging MBH patients? | G19: X | H19: X | I19: X | J19: X | K19: {=SUMPRODUCT(IFERROR(VLOOKUP(N19:AR19,'Response Options'!$D$5:$E$10,2,FALSE),0))/COUNTA(N19:AR19)} -> 3.6923077 | L19: =ROUND(K19,0) -> 4 | M19: =_xlfn.XLOOKUP(L19,'Response Options'!$E$5:$E$10,'Response Options'!$D$5:$D$10) -> Extremely Important | N19: ='Outcome Priotization'!$F$12 -> Critically Important / Essential | O19: ='Outcome Priotization'!F13 -> Moderately Important | P19: ='Outcome Priotization'!F14 -> Critically Important / Essential | R19: ='Outcome Priotization'!F16 -> Critically Important / Essential | S19: ='Outcome Priotization'!F17 -> Very Important | U19: ='Outcome Priotization'!F19 -> Critically Important / Essential | X19: ='Outcome Priotization'!F22 -> Slightly unimportant | Y19: ='Outcome Priotization'!F23 -> Very Important | AA19: ='Outcome Priotization'!F25 -> Critically Important / Essential | AC19: ='Outcome Priotization'!F27 -> Moderately Important | AI19: ='Outcome Priotization'!F33 -> Critically Important / Essential | AN19: ='Outcome Priotization'!F38 -> Very Important | AQ19: ='Outcome Priotization'!F41 -> Critically Important / Essential
E20: b. How do you anticipate minimizing ligature points in the triaging space? | G20: X | H20: X | I20: X | J20: X
E21: c. How do you anticipate maintaining privacy in the ED triage room? | G21: X | H21: X | I21: X | J21: X
B22: 4 | C22: Bed Allocation:
B23: 4.1 | C23: What is your anticipated policy/process for allocating MBH patients in the ED care spaces? | E23: a. Where do you anticipate locating MBH patient care spaces in the ED to improve situational awareness? | G23: X | H23: X | I23: X | J23: X | K23: {=SUMPRODUCT(IFERROR(VLOOKUP(N23:AR23,'Response Options'!$D$5:$E$10,2,FALSE),0))/COUNTA(N23:AR23)} -> 3.5789474 | L23: =ROUND(K23,0) -> 4 | M23: =_xlfn.XLOOKUP(L23,'Response Options'!$E$5:$E$10,'Response Options'!$D$5:$D$10) -> Extremely Important | N23: ='Outcome Priotization'!$F$12 -> Critically Important / Essential | O23: ='Outcome Priotization'!F13 -> Moderately Important | P23: ='Outcome Priotization'!F14 -> Critically Important / Essential | Q23: ='Outcome Priotization'!F15 -> Slightly important | R23: ='Outcome Priotization'!F16 -> Critically Important / Essential | S23: ='Outcome Priotization'!F17 -> Very Important | U23: ='Outcome Priotization'!F19 -> Critically Important / Essential | V23: ='Outcome Priotization'!F20 -> Critically Important / Essential | W23: ='Outcome Priotization'!F21 -> Extremely Important | Y23: ='Outcome Priotization'!F23 -> Very Important | AA23: ='Outcome Priotization'!F25 -> Critically Important / Essential | AC23: ='Outcome Priotization'!F27 -> Moderately Important | AH23: ='Outcome Priotization'!F32 -> Very Important | AI23: ='Outcome Priotization'!F33 -> Critically Important / Essential | AN23: ='Outcome Priotization'!F38 -> Very Important | AO23: ='Outcome Priotization'!F39 -> Slightly unimportant | AP23: ='Outcome Priotization'!F40 -> Critically Important / Essential | AQ23: ='Outcome Priotization'!F41 -> Critically Important / Essential | AR23: ='Outcome Priotization'!F42 -> Moderately Important
E24: b. If you intend to use any specific technology/equipment (e.g. cameras) to improve situational awareness, where do you anticipate locating them? Where do you anticipate locating the screens that will be used for monitored? | G24: X | H24: X | I24: X | J24: X
E25: c. Do you anticipate using the same room for MBH and non-MBH patients? | G25: X | H25: X | I25: X | J25: X
E26: d. Do you anticipate having dedicated MBH rooms in the ED? How many? | G26: X | H26: X | I26: X | J26: X
E27: e. Do you anticipate having specific pediatric MBH friendly ED exam rooms? How many? | G27: X | H27: X | I27: X | J27: X
B28: 4.2 | C28: How do you anticipate adapting/ligature-minimizing patient rooms for the needs of MBH patients and dual diagnosis patients? | E28: a. Where do you anticipate storing the equipment and supplies while ligature-minimizing the room? | G28: X | H28: X | I28: X | J28: X | K28: {=SUMPRODUCT(IFERROR(VLOOKUP(N28:AR28,'Response Options'!$D$5:$E$10,2,FALSE),0))/COUNTA(N28:AR28)} -> 3.6153846 | L28: =ROUND(K28,0) -> 4 | M28: =_xlfn.XLOOKUP(L28,'Response Options'!$E$5:$E$10,'Response Options'!$D$5:$D$10) -> Extremely Important | N28: ='Outcome Priotization'!$F$12 -> Critically Important / Essential | Q28: ='Outcome Priotization'!F15 -> Slightly important | S28: ='Outcome Priotization'!F17 -> Very Important | U28: ='Outcome Priotization'!F19 -> Critically Important / Essential | W28: ='Outcome Priotization'!F21 -> Extremely Important | X28: ='Outcome Priotization'!F22 -> Slightly unimportant | Y28: ='Outcome Priotization'!F23 -> Very Important | Z28: ='Outcome Priotization'!F24 -> Critically Important / Essential | AA28: ='Outcome Priotization'!F25 -> Critically Important / Essential | AI28: ='Outcome Priotization'!F33 -> Critically Important / Essential | AK28: ='Outcome Priotization'!F35 -> Slightly important | AP28: ='Outcome Priotization'!F40 -> Critically Important / Essential | AQ28: ='Outcome Priotization'!F41 -> Critically Important / Essential
E29: b. Do you plan to implement flexible ED-exam rooms that may be used for both MBH and non-MBH patients? | G29: X | H29: X | I29: X | J29: X
B30: 4.3 | C30: Do you anticipate placing MBH patients in hallway beds? What type of MBH patients do you anticipate placing in hallway beds? | E30: a. Do you anticipate having designated areas for dedicated hallway beds for MBH patients? Where would you prefer them? | G30: X | H30: X | I30: X | J30: X | K30: {=SUMPRODUCT(IFERROR(VLOOKUP(N30:AR30,'Response Options'!$D$5:$E$10,2,FALSE),0))/COUNTA(N30:AR30)} -> 3.7142857 | L30: =ROUND(K30,0) -> 4 | M30: =_xlfn.XLOOKUP(L30,'Response Options'!$E$5:$E$10,'Response Options'!$D$5:$D$10) -> Extremely Important | N30: ='Outcome Priotization'!$F$12 -> Critically Important / Essential | O30: ='Outcome Priotization'!F13 -> Moderately Important | P30: ='Outcome Priotization'!F14 -> Critically Important / Essential | Q30: ='Outcome Priotization'!F15 -> Slightly important | R30: ='Outcome Priotization'!F16 -> Critically Important / Essential | S30: ='Outcome Priotization'!F17 -> Very Important | U30: ='Outcome Priotization'!F19 -> Critically Important / Essential | V30: ='Outcome Priotization'!F20 -> Critically Important / Essential | W30: ='Outcome Priotization'!F21 -> Extremely Important | X30: ='Outcome Priotization'!F22 -> Slightly unimportant | Z30: ='Outcome Priotization'!F24 -> Critically Important / Essential | AA30: ='Outcome Priotization'!F25 -> Critically Important / Essential | AG30: ='Outcome Priotization'!F31 -> Critically Important / Essential | AH30: ='Outcome Priotization'!F32 -> Very Important | AI30: ='Outcome Priotization'!F33 -> Critically Important / Essential | AJ30: ='Outcome Priotization'!F34 -> Critically Important / Essential | AN30: ='Outcome Priotization'!F38 -> Very Important | AO30: ='Outcome Priotization'!F39 -> Slightly unimportant | AP30: ='Outcome Priotization'!F40 -> Critically Important / Essential | AQ30: ='Outcome Priotization'!F41 -> Critically Important / Essential | AR30: ='Outcome Priotization'!F42 -> Moderately Important
E31: b. How do you anticipate using hallway beds for providing care to MBH patients? | H31: X | I31: X | J31: X
E32: c. Where do you anticipate having private conversations with MBH patients during assessments in hallways beds? | G32: X | H32: X | I32: X | J32: X
E33: d. Where do you anticipate having private conversations with care partners of MBH patients during assessments in hallways beds? | G33: X | H33: X | I33: X | J33: X
E34: e. How do you anticipate improving safety and minimizing ligature risks for MBH patients in hallway beds? | G34: X | H34: X | I34: X | J34: X
B35: 4.4 | C35: Do you have a policy/process for preventing elopement? | E35: a. What features/equipment do you anticipate using within the ED to prevent elopement for MBH patient? | G35: X | H35: X | I35: X | J35: X | K35: {=SUMPRODUCT(IFERROR(VLOOKUP(N35:AR35,'Response Options'!$D$5:$E$10,2,FALSE),0))/COUNTA(N35:AR35)} -> 3.6666667 | L35: =ROUND(K35,0) -> 4 | M35: =_xlfn.XLOOKUP(L35,'Response Options'!$E$5:$E$10,'Response Options'!$D$5:$D$10) -> Extremely Important | O35: ='Outcome Priotization'!F13 -> Moderately Important | P35: ='Outcome Priotization'!F14 -> Critically Important / Essential | Q35: ='Outcome Priotization'!F15 -> Slightly important | R35: ='Outcome Priotization'!F16 -> Critically Important / Essential | S35: ='Outcome Priotization'!F17 -> Very Important | V35: ='Outcome Priotization'!F20 -> Critically Important / Essential | W35: ='Outcome Priotization'!F21 -> Extremely Important | Y35: ='Outcome Priotization'!F23 -> Very Important | AA35: ='Outcome Priotization'!F25 -> Critically Important / Essential
B36: 4.5 | C36: How do you anticipate managing high volumes of MBH patients? | E36: a. Where do you anticipate accommodating high volumes of MBH patients? | G36: X | H36: X | I36: X | J36: X | K36: {=SUMPRODUCT(IFERROR(VLOOKUP(N36:AR36,'Response Options'!$D$5:$E$10,2,FALSE),0))/COUNTA(N36:AR36)} -> 3.7894737 | L36: =ROUND(K36,0) -> 4 | M36: =_xlfn.XLOOKUP(L36,'Response Options'!$E$5:$E$10,'Response Options'!$D$5:$D$10) -> Extremely Important | O36: ='Outcome Priotization'!F13 -> Moderately Important | P36: ='Outcome Priotization'!F14 -> Critically Important / Essential | Q36: ='Outcome Priotization'!F15 -> Slightly important | R36: ='Outcome Priotization'!F16 -> Critically Important / Essential | S36: ='Outcome Priotization'!F17 -> Very Important | U36: ='Outcome Priotization'!F19 -> Critically Important / Essential | V36: ='Outcome Priotization'!F20 -> Critically Important / Essential | W36: ='Outcome Priotization'!F21 -> Extremely Important | X36: ='Outcome Priotization'!F22 -> Slightly unimportant | Z36: ='Outcome Priotization'!F24 -> Critically Important / Essential | AA36: ='Outcome Priotization'!F25 -> Critically Important / Essential | AB36: ='Outcome Priotization'!F26 -> Extremely Important | AG36: ='Outcome Priotization'!F31 -> Critically Important / Essential | AH36: ='Outcome Priotization'!F32 -> Very Important | AI36: ='Outcome Priotization'!F33 -> Critically Important / Essential | AJ36: ='Outcome Priotization'!F34 -> Critically Important / Essential | AO36: ='Outcome Priotization'!F39 -> Slightly unimportant | AP36: ='Outcome Priotization'!F40 -> Critically Important / Essential | AQ36: ='Outcome Priotization'!F41 -> Critically Important / Essential
B37: 4.6 | C37: For general EDs: What is your anticipated policy/process for separating pediatric, adolescent, and adult MBH patients in the ED? | E37: a. Where do you anticipate locating spaces for adult and pediatric MBH patients in the ED? | G37: X | H37: X | I37: X | J37: X | K37: {=SUMPRODUCT(IFERROR(VLOOKUP(N37:AR37,'Response Options'!$D$5:$E$10,2,FALSE),0))/COUNTA(N37:AR37)} -> 3.6666667 | L37: =ROUND(K37,0) -> 4 | M37: =_xlfn.XLOOKUP(L37,'Response Options'!$E$5:$E$10,'Response Options'!$D$5:$D$10) -> Extremely Important | Q37: ='Outcome Priotization'!F15 -> Slightly important | S37: ='Outcome Priotization'!F17 -> Very Important | U37: ='Outcome Priotization'!F19 -> Critically Important / Essential | W37: ='Outcome Priotization'!F21 -> Extremely Important | Y37: ='Outcome Priotization'!F23 -> Very Important | AA37: ='Outcome Priotization'!F25 -> Critically Important / Essential | AG37: ='Outcome Priotization'!F31 -> Critically Important / Essential | AH37: ='Outcome Priotization'!F32 -> Very Important | AI37: ='Outcome Priotization'!F33 -> Critically Important / Essential | AO37: ='Outcome Priotization'!F39 -> Slightly unimportant | AP37: ='Outcome Priotization'!F40 -> Critically Important / Essential | AQ37: ='Outcome Priotization'!F41 -> Critically Important / Essential
B38: 4.7 | C38: For pediatric EDs: What is your anticipated policy/process for separating adolescent MBH patients? | E38: a. Where do you anticipate locating adolescent or older pediatric MBH patients? | G38: X | H38: X | I38: X | J38: X | K38: {=SUMPRODUCT(IFERROR(VLOOKUP(N38:AR38,'Response Options'!$D$5:$E$10,2,FALSE),0))/COUNTA(N38:AR38)} -> 3.6666667 | L38: =ROUND(K38,0) -> 4 | M38: =_xlfn.XLOOKUP(L38,'Response Options'!$E$5:$E$10,'Response Options'!$D$5:$D$10) -> Extremely Important | Q38: ='Outcome Priotization'!F15 -> Slightly important | S38: ='Outcome Priotization'!F17 -> Very Important | U38: ='Outcome Priotization'!F19 -> Critically Important / Essential | W38: ='Outcome Priotization'!F21 -> Extremely Important | Y38: ='Outcome Priotization'!F23 -> Very Important | AA38: ='Outcome Priotization'!F25 -> Critically Important / Essential | AG38: ='Outcome Priotization'!F31 -> Critically Important / Essential | AH38: ='Outcome Priotization'!F32 -> Very Important | AI38: ='Outcome Priotization'!F33 -> Critically Important / Essential | AO38: ='Outcome Priotization'!F39 -> Slightly unimportant | AP38: ='Outcome Priotization'!F40 -> Critically Important / Essential | AQ38: ='Outcome Priotization'!F41 -> Critically Important / Essential
C39: Diagnostic Consideration
B40: 5 | C40: Changing:
...

Sheet Guideline Prioritization
C5: Design Guidelines Prioritization Worksheet
C7: Refer to the Design Guidelines chapter of the Toolkit Companion Book to learn about each of the design guidelines. This prioritization worksheet shows how important each guideline is for your project, according to related objectives and their priorities
C8: Review the importance based on outcome prioritization, then select from the options in the dropdown menu in the "Review Importance" column to either confirm or adjust the levels of importance for each guideline
C10: Category | D10: Guideline | E10: Related Outcomes | N10: Importance based on Outcome priotization | O10: Review Importance
E11: Improve Safety & Security | F11: Optimize Efficiency & Effectiveness | G11: Improve Communication | H11: Improve Overall Comfort for all users | I11: Improve Patient and Family Agency | J11: Provide Choice & Control | K11: Sum | L11: Mean | M11: Round
C12: Patient Safety | D12: 1. Maximize staff's situational awareness of the patient | E12: {=_xlfn.XLOOKUP("Improve Safety & Security",_xlfn.ANCHORARRAY( 'Outcome Priotization'!K12),'Outcome Priotization'!L12:L17)} -> First priority | K12: {=SUMPRODUCT(IFERROR(VLOOKUP(E12:J12,'Response Options'!D14:E19,2,FALSE),0))} -> 6 | L12: =K12/1 -> 6 | M12: =ROUND(L12,0) -> 6 | N12: =_xlfn.XLOOKUP(M12,'Response Options'!F5:F10,'Response Options'!D5:D10) -> Critically Important / Essential | O12: Critically Important / Essential
D13: 2. Reduce opportunities for the patient to cause harm | E13: {=_xlfn.XLOOKUP("Improve Safety & Security",_xlfn.ANCHORARRAY( 'Outcome Priotization'!K12),'Outcome Priotization'!L12:L17)} -> First priority | F13: {=_xlfn.XLOOKUP("Optimize Efficiency & Effectiveness",_xlfn.ANCHORARRAY( 'Outcome Priotization'!K12),'Outcome Priotization'!L12:L17)} -> Fourth priority | H13: {=_xlfn.XLOOKUP("Improve Overall Comfort for all users",_xlfn.ANCHORARRAY( 'Outcome Priotization'!K12),'Outcome Priotization'!L12:L17)} -> Third priority | K13: {=SUMPRODUCT(IFERROR(VLOOKUP(E13:J13,'Response Options'!D14:E19,2,FALSE),0))} -> 13 | L13: =K13/3 -> 4.3333333 | M13: =ROUND(L13,0) -> 4 | N13: =_xlfn.XLOOKUP(M13,'Response Options'!F5:F10,'Response Options'!D5:D10) -> Very Important | O13: Very Important
D14: 3. Enhance sense of security for the patient and caregiver | E14: {=_xlfn.XLOOKUP("Improve Safety & Security",_xlfn.ANCHORARRAY( 'Outcome Priotization'!K12),'Outcome Priotization'!L12:L17)} -> First priority | H14: {=_xlfn.XLOOKUP("Improve Overall Comfort for all users",_xlfn.ANCHORARRAY( 'Outcome Priotization'!K12),'Outcome Priotization'!L12:L17)} -> Third priority | K14: {=SUMPRODUCT(IFERROR(VLOOKUP(E14:J14,'Response Options'!D14:E19,2,FALSE),0))} -> 10 | L14: =K14/3 -> 3.3333333 | M14: =ROUND(L14,0) -> 3 | N14: =_xlfn.XLOOKUP(M14,'Response Options'!F5:F10,'Response Options'!D5:D10) -> Moderately Important | O14: Moderately Important
C15: Worker Safety & Effectiveness | D15: 4. Optimize staff workflow | E15: {=_xlfn.XLOOKUP("Improve Safety & Security",_xlfn.ANCHORARRAY( 'Outcome Priotization'!K12),'Outcome Priotization'!L12:L17)} -> First priority | F15: {=_xlfn.XLOOKUP("Optimize Efficiency & Effectiveness",_xlfn.ANCHORARRAY( 'Outcome Priotization'!K12),'Outcome Priotization'!L12:L17)} -> Fourth priority | G15: {=_xlfn.XLOOKUP("Improve Communication",_xlfn.ANCHORARRAY( 'Outcome Priotization'!K12),'Outcome Priotization'!L12:L17)} -> Sixth priority | H15: {=_xlfn.XLOOKUP("Improve Overall Comfort for all users",_xlfn.ANCHORARRAY( 'Outcome Priotization'!K12),'Outcome Priotization'!L12:L17)} -> Third priority | K15: {=SUMPRODUCT(IFERROR(VLOOKUP(E15:J15,'Response Options'!D14:E19,2,FALSE),0))} -> 14 | L15: =K15/3 -> 4.6666667 | M15: =ROUND(L15,0) -> 5 | N15: =_xlfn.XLOOKUP(M15,'Response Options'!F5:F10,'Response Options'!D5:D10) -> Extremely Important | O15: Very Important
D16: 5. Improve safety and security for staff | E16: {=_xlfn.XLOOKUP("Improve Safety & Security",_xlfn.ANCHORARRAY( 'Outcome Priotization'!K12),'Outcome Priotization'!L12:L17)} -> First priority | K16: {=SUMPRODUCT(IFERROR(VLOOKUP(E16:J16,'Response Options'!D14:E19,2,FALSE),0))} -> 6 | L16: =K16/3 -> 2 | M16: =ROUND(L16,0) -> 2 | N16: =_xlfn.XLOOKUP(M16,'Response Options'!F5:F10,'Response Options'!D5:D10) -> Slightly important | O16: Slightly important
D17: 6. Provide flexible and adaptable work environments | E17: {=_xlfn.XLOOKUP("Improve Safety & Security",_xlfn.ANCHORARRAY( 'Outcome Priotization'!K12),'Outcome Priotization'!L12:L17)} -> First priority | F17: {=_xlfn.XLOOKUP("Optimize Efficiency & Effectiveness",_xlfn.ANCHORARRAY( 'Outcome Priotization'!K12),'Outcome Priotization'!L12:L17)} -> Fourth priority | K17: {=SUMPRODUCT(IFERROR(VLOOKUP(E17:J17,'Response Options'!D14:E19,2,FALSE),0))} -> 9 | L17: =K17/3 -> 3 | M17: =ROUND(L17,0) -> 3 | N17: =_xlfn.XLOOKUP(M17,'Response Options'!F5:F10,'Response Options'!D5:D10) -> Moderately Important | O17: Moderately Important
D18: 7. Provide opportunities for staff respite | H18: {=_xlfn.XLOOKUP("Improve Overall Comfort for all users",_xlfn.ANCHORARRAY( 'Outcome Priotization'!K12),'Outcome Priotization'!L12:L17)} -> Third priority | K18: {=SUMPRODUCT(IFERROR(VLOOKUP(E18:J18,'Response Options'!D14:E19,2,FALSE),0))} -> 4 | L18: =K18/3 -> 1.3333333 | M18: =ROUND(L18,0) -> 1 | N18: =_xlfn.XLOOKUP(M18,'Response Options'!F5:F10,'Response Options'!D5:D10) -> Not Important | O18: Slightly important
D19: 8. Support effective communication among staff | F19: {=_xlfn.XLOOKUP("Optimize Efficiency & Effectiveness",_xlfn.ANCHORARRAY( 'Outcome Priotization'!K12),'Outcome Priotization'!L12:L17)} -> Fourth priority | G19: {=_xlfn.XLOOKUP("Improve Communication",_xlfn.ANCHORARRAY( 'Outcome Priotization'!K12),'Outcome Priotization'!L12:L17)} -> Sixth priority | H19: {=_xlfn.XLOOKUP("Improve Overall Comfort for all users",_xlfn.ANCHORARRAY( 'Outcome Priotization'!K12),'Outcome Priotization'!L12:L17)} -> Third priority | K19: {=SUMPRODUCT(IFERROR(VLOOKUP(E19:J19,'Response Options'!D14:E19,2,FALSE),0))} -> 8 | L19: =K19/3 -> 2.6666667 | M19: =ROUND(L19,0) -> 3 | N19: =_xlfn.XLOOKUP(M19,'Response Options'!F5:F10,'Response Options'!D5:D10) -> Moderately Important | O19: Very Important
C20: Patient Care Quality & Experience | D20: 9. Provide opportunities for engaging patients and care partners | G20: {=_xlfn.XLOOKUP("Improve Communication",_xlfn.ANCHORARRAY( 'Outcome Priotization'!K12),'Outcome Priotization'!L12:L17)} -> Sixth priority | H20: {=_xlfn.XLOOKUP("Improve Overall Comfort for all users",_xlfn.ANCHORARRAY( 'Outcome Priotization'!K12),'Outcome Priotization'!L12:L17)} -> Third priority | I20: {=_xlfn.XLOOKUP("Improve Patient and Family Agency",_xlfn.ANCHORARRAY( 'Outcome Priotization'!K12),'Outcome Priotization'!L12:L17)} -> Fifth priority | K20: {=SUMPRODUCT(IFERROR(VLOOKUP(E20:J20,'Response Options'!D14:E19,2,FALSE),0))} -> 7 | L20: =K20/3 -> 2.3333333 | M20: =ROUND(L20,0) -> 2 | N20: =_xlfn.XLOOKUP(M20,'Response Options'!F5:F10,'Response Options'!D5:D10) -> Slightly important | O20: Slightly important
D21: 10. Support patient and family dignity and comfort | H21: {=_xlfn.XLOOKUP("Improve Overall Comfort for all users",_xlfn.ANCHORARRAY( 'Outcome Priotization'!K12),'Outcome Priotization'!L12:L17)} -> Third priority | I21: {=_xlfn.XLOOKUP("Improve Patient and Family Agency",_xlfn.ANCHORARRAY( 'Outcome Priotization'!K12),'Outcome Priotization'!L12:L17)} -> Fifth priority | J21: {=_xlfn.XLOOKUP("Provide Patient Choice and Control",_xlfn.ANCHORARRAY( 'Outcome Priotization'!K12),'Outcome Priotization'!L12:L17)} -> Second priority | K21: {=SUMPRODUCT(IFERROR(VLOOKUP(E21:J21,'Response Options'!D14:E19,2,FALSE),0))} -> 11 | L21: =K21/3 -> 3.6666667 | M21: =ROUND(L21,0) -> 4 | N21: =_xlfn.XLOOKUP(M21,'Response Options'!F5:F10,'Response Options'!D5:D10) -> Very Important | O21: Very Important
D22: 11. Create opportunities for auditory and visual privacy | E22: {=_xlfn.XLOOKUP("Improve Safety & Security",_xlfn.ANCHORARRAY( 'Outcome Priotization'!K12),'Outcome Priotization'!L12:L17)} -> First priority | G22: {=_xlfn.XLOOKUP("Improve Communication",_xlfn.ANCHORARRAY( 'Outcome Priotization'!K12),'Outcome Priotization'!L12:L17)} -> Sixth priority | H22: {=_xlfn.XLOOKUP("Improve Overall Comfort for all users",_xlfn.ANCHORARRAY( 'Outcome Priotization'!K12),'Outcome Priotization'!L12:L17)} -> Third priority | I22: {=_xlfn.XLOOKUP("Improve Patient and Family Agency",_xlfn.ANCHORARRAY( 'Outcome Priotization'!K12),'Outcome Priotization'!L12:L17)} -> Fifth priority | J22: {=_xlfn.XLOOKUP("Provide Patient Choice and Control",_xlfn.ANCHORARRAY( 'Outcome Priotization'!K12),'Outcome Priotization'!L12:L17)} -> Second priority | K22: {=SUMPRODUCT(IFERROR(VLOOKUP(E22:J22,'Response Options'!D14:E19,2,FALSE),0))} -> 18 | L22: =K22/3 -> 6 | M22: =ROUND(L22,0) -> 6 | N22: =_xlfn.XLOOKUP(M22,'Response Options'!F5:F10,'Response Options'!D5:D10) -> Critically Important / Essential | O22: Critically Important / Essential
D23: 12. Provide patient choice and control over the environment | H23: {=_xlfn.XLOOKUP("Improve Overall Comfort for all users",_xlfn.ANCHORARRAY( 'Outcome Priotization'!K12),'Outcome Priotization'!L12:L17)} -> Third priority | J23: {=_xlfn.XLOOKUP("Provide Patient Choice and Control",_xlfn.ANCHORARRAY( 'Outcome Priotization'!K12),'Outcome Priotization'!L12:L17)} -> Second priority | K23: {=SUMPRODUCT(IFERROR(VLOOKUP(E23:J23,'Response Options'!D14:E19,2,FALSE),0))} -> 9 | L23: =K23/3 -> 3 | M23: =ROUND(L23,0) -> 3 | N23: =_xlfn.XLOOKUP(M23,'Response Options'!F5:F10,'Response Options'!D5:D10) -> Moderately Important | O23: Moderately Important
D24: 13. Create opportunities for sensory-friendly support | H24: {=_xlfn.XLOOKUP("Improve Overall Comfort for all users",_xlfn.ANCHORARRAY( 'Outcome Priotization'!K12),'Outcome Priotization'!L12:L17)} -> Third priority | I24: {=_xlfn.XLOOKUP("Improve Patient and Family Agency",_xlfn.ANCHORARRAY( 'Outcome Priotization'!K12),'Outcome Priotization'!L12:L17)} -> Fifth priority | J24: {=_xlfn.XLOOKUP("Provide Patient Choice and Control",_xlfn.ANCHORARRAY( 'Outcome Priotization'!K12),'Outcome Priotization'!L12:L17)} -> Second priority | K24: {=SUMPRODUCT(IFERROR(VLOOKUP(E24:J24,'Response Options'!D14:E19,2,FALSE),0))} -> 11 | L24: =K24/3 -> 3.6666667 | M24: =ROUND(L24,0) -> 4 | N24: =_xlfn.XLOOKUP(M24,'Response Options'!F5:F10,'Response Options'!D5:D10) -> Very Important | O24: Moderately Important
C25: Organizational Performance | D25: 14.Support clarity and anticipation of the care path and steps in the healthcare experience. | H25: {=_xlfn.XLOOKUP("Improve Overall Comfort for all users",_xlfn.ANCHORARRAY( 'Outcome Priotization'!K12),'Outcome Priotization'!L12:L17)} -> Third priority | I25: {=_xlfn.XLOOKUP("Improve Patient and Family Agency",_xlfn.ANCHORARRAY( 'Outcome Priotization'!K12),'Outcome Priotization'!L12:L17)} -> Fifth priority | J25: {=_xlfn.XLOOKUP("Provide Patient Choice and Control",_xlfn.ANCHORARRAY( 'Outcome Priotization'!K12),'Outcome Priotization'!L12:L17)} -> Second priority | K25: {=SUMPRODUCT(IFERROR(VLOOKUP(E25:J25,'Response Options'!D14:E19,2,FALSE),0))} -> 11 | L25: =K25/3 -> 3.6666667 | M25: =ROUND(L25,0) -> 4 | N25: =_xlfn.XLOOKUP(M25,'Response Options'!F5:F10,'Response Options'!D5:D10) -> Very Important | O25: Moderately Important
D26: 15. Provide timely access to psychiatric care | E26: {=_xlfn.XLOOKUP("Improve Safety & Security",_xlfn.ANCHORARRAY( 'Outcome Priotization'!K12),'Outcome Priotization'!L12:L17)} -> First priority | F26: {=_xlfn.XLOOKUP("Optimize Efficiency & Effectiveness",_xlfn.ANCHORARRAY( 'Outcome Priotization'!K12),'Outcome Priotization'!L12:L17)} -> Fourth priority | H26: {=_xlfn.XLOOKUP("Improve Overall Comfort for all users",_xlfn.ANCHORARRAY( 'Outcome Priotization'!K12),'Outcome Priotization'!L12:L17)} -> Third priority | I26: {=_xlfn.XLOOKUP("Improve Patient and Family Agency",_xlfn.ANCHORARRAY( 'Outcome Priotization'!K12),'Outcome Priotization'!L12:L17)} -> Fifth priority | K26: {=SUMPRODUCT(IFERROR(VLOOKUP(E26:J26,'Response Options'!D14:E19,2,FALSE),0))} -> 15 | L26: =K26/3 -> 5 | M26: =ROUND(L26,0) -> 5 | N26: =_xlfn.XLOOKUP(M26,'Response Options'!F5:F10,'Response Options'!D5:D10) -> Extremely Important | O26: Critically Important / Essential

Sheet Design alignement tool
C1: DESIGN ALIGNEMENT TOOL | G1: Relevant Design Objectives/Outcomes
C2: Date: __________ | D2: Review each design strategy and their association to guidelines, then select from the options in the dropdown menu in the "Successfully implemented?" to mark if the strategies have been incorporated into your design concept. | G2: Improve Safety & Security | P2: Optimize Efficiency & Effectiveness | U2: Improve Communication | Z2: Improve Overall Comfort for All Users | AE2: Improve Patient and Family Agency | AI2: Provide Patient Choice and Control
A3: Category | B3: Importance | C3: Guideline | D3: Design Strategy | E3: Successfully Implemented? | F3: Design Features | G3: Preventing Self Harm | H3: Preveting Elopement | I3: Quicker response in emergency events | J3: Perception of safety | K3: Quick response to patient-initiated harm | L3: Reduce harm aggainst others | M3: Reduce need for restraints | N3: Reduce exposure to triggering content | O3: Enhances patient visibility | P3: Reduce staff workload (physical and cognitive) | Q3: Reduce ED waiting times and/or length of stay | R3: Adequate care for co-occurring med/psych conditions | S3: Improved coordination of patient flow | T3: Provision of appropriate psych care in the ED | U3: Enhance team coordination and collaboration | V3: Quick response from medical team | W3: Streamlined flow of information | X3: Support staff and resident training | Y3: Reduced miscommunication with family members | Z3: Enhance Patient and family satisfaction | AA3: Improve Patient and family comfort | AB3: Reduce anxiety | AC3: Reduce crowding | AD3: Enhanced staff satisfaction | AE3: Facilitating family participation in care | AF3: Promoting trust and rapport | AG3: Safeguard patient confidential information | AH3: Limits being seen by others | AI3: Reduce agitation & boredom | AJ3: Enhance sense of dignity | AK3: Improve emotional & sleep regulation | AL3: Notes | AM3: Conflicts
A4: Patient Safety | B4: ='Guideline Prioritization'!O12 -> Critically Important / Essential | C4: 1. Maximize staff's situational awareness of the patient | D4: 1.1The patient's head and limbs can be seen from the hallway when they are in the bed/chair. | E4: Yes | F4: Architectural Elements | G4: ● | O4: ● | AM4: 3.2 | AN4: 3.1
D5: 1.2. There are no blind spots or hiding spots inside the room when looking from the hallway/doorway. | E5: Yes | F5: Architectural Elements | G5: ● | O5: ● | AM5: 3.2
D6: 1.4. Surveillance cameras provide direct visual access to the room's door(s) and any other access points. | E6: Maybe | F6: Architectural Elements | H6: ● | I6: ● | O6: ●
D7: 1.5 Surveillance cameras are discretely integrated into the design. | E7: No | F7: Technology & other elements | I7: ● | O7: ● | AL7: (e.g., with custom camera covers or built-in fixtures)
D8: 1.6. Doors do not lock from the inside. If present, any locks are on the outside (department/hallway side) of the door. | E8: Maybe | F8: Architectural Elements | H8: ● | I8: ● | O8: ●
D9: 1.7. Space for an observer (chair, alcove, etc.) is positioned so that it has direct visual access to the room's door(s) and any other access points. | E9: Yes | F9: Architectural Elements | H9: ● | O9: ●
B10: ='Guideline Prioritization'!O13 -> Very Important | C10: 2. Reduce opportunities for the patient to cause harm | D10: 2.1. If located in the room, the sink and all its parts (handles, faucets, etc.) are ligature-minimized and tamper-resistant. | E10: Yes | F10: MEP & Building Systems | G10: ● | L10: ● | M10: ● | P10: ●
D11: 2.2. If located in the room, the computer workstation and all its parts (mounting, monitor, cords, etc.) are removable and/or ligature-minimized and tamper-resistant. | E11: Yes | F11: Technology & Other Elements | G11: ● | L11: ● | M11: ●
D12: 2.3. Any televisions and/or entertainment devices in the room and all their parts ( screens, controls, etc.) are ligature-minimized and tamper-resistant. | E12: Yes | F12: Technology & Other Elements | G12: ● | L12: ● | M12: ● | P12: ●
D13: 2.4. Any emergency call buttons or other communication devices in the room are ligature-minimized and tamper-resistant. | E13: Yes | F13: Technology & Other Elements | G13: ● | J13: ● | L13: ● | M13: ● | P13: ●
D14: 2.5. Any dispensers or other accessories present in the room are ligature-minimized and tamper-resistant. | E14: Yes | F14: Furnishings & Finishes | G14: ● | L14: ● | M14: ● | P14: ●
D15: 2.6. Every element in the room that could pose a ligature or weaponization risk can be made inaccessible to patients. | E15: Maybe | F15: Architectural Elements | G15: ● | L15: ● | M15: ● | AL15: (e.g. medical equipment, supplies, sharps container, communication boards, soap and gloves, decorative elements, etc.) | AM15: 10.2 | AN15: 3.5 | AQ15: verify conflicts
D16: 2.7. The patient does not have any access to slats, cords, mechanical components or any other parts of window treatments that could pose a weaponization, harm, or ligature risk. | E16: Yes | F16: Architectural Elements | G16: ● | L16: ● | M16: ● | P16: ●
D17: 2.8. Furniture, fixtures, and surfaces do not have sharp edges, protruding elements, joints, or gaps that could be used for weaponization, harm, or ligature. | E17: Yes | F17: Furnishings & Finishes | G17: ● | L17: ● | M17: ● | P17: ●
D18: 2.9. Casework and hardware are ligature-minimized and tamper-resistant. | E18: Yes | F18: Furnishings & Finishes | G18: ● | L18: ● | M18: ●
D19: 2.10. Casework and furnishings are designed to prevent patients from climbing. | E19: Yes | F19: Furnishings & Finishes | G19: ● | L19: ● | M19: ● | P19: ●
D20: 2.11. All electrical and mechanical fixtures (including switches, receptacles, grilles, etc.) are ligature-minimized and tamper-resistant. | E20: Yes | F20: MEP & Building Systems | G20: ● | L20: ● | M20: ● | P20: ●
D21: 2.12. The ceiling is ligature-minimized and tamper-resistant. | E21: Yes | F21: Furnishings & Finishes | G21: ● | L21: ● | M21: ● | P21: ●
B22: ='Guideline Prioritization'!O14 -> Moderately Important | C22: 3. Enhance sense of security for the patient and caregiver | D22: 3.1. The patient bed/chair is oriented away from direct view of the hallway to minimize the patient's exposure to ED activities that may be over-stimulating or distressing. | E22: No | F22: Architectural Elements | N22: ● | AB22: ● | AH22: ● | AM22: 1.1
D23: 3.2 The room's design minimizes direct visual exposure of the patient from the hallway. | E23: Yes | F23: Architectural Elements | N23: ● | AB23: ● | AH23: ● | AL23: (e.g., angled alcove/surveillance bay or small observation windows) | AM23: 1.1 | AN23: 1.2
D24: 3.3. The emergency call button and/or communication device is easily accessible from the patient bed/chair. | E24: Yes | F24: Technology & Other Elements | K24: ● | AB24: ●
D25: 3.4.The emergency call button and/or communication device is easily accessible to the care partner(s). | E25: Yes | F25: Technology & Other Elements | L25: ● | N25: ● | AB25: ●
D26: 3.5. Staff can supervise and/or curate entertainment and media options accessible to the patient | E26: Yes | F26: Technology & Other Elements | AM26: 2.6
A27: Worker Safety & Effectiveness | B27: ='Guideline Prioritization'!O15 -> Very Important | C27: 4. Optimize staff workflow | D27: 4.1. The sink (either inside or outside the room) is immediately visible and accessible to the room's entrance. | E27: Yes | F27: Architectural Elements | P27: ●
D28: 4.2. Hand sanitizer, gloves, and other PPE are immediately accessible and visible to the room's entrance. | E28: Yes | F28: Furnishings & Finishes | P28: ●
D29: 4.3. There is a dedicated surface near the sink for placing items during handwashing. | E29: Yes | F29: Architectural Elements | P29: ● | AA29: ● | AL29: Having a surface near the sink can be used for self-care. (brushing teeth, washing the face).
D30: 4.4. All fixtures, finishes, and furnishings are easy to clean. | E30: Yes | F30: Furnishings & Finishes | P30: ●
D31: 4.5. The waste bin is easy for staff members to access while being out of the patient's immediate reach. | E31: Yes | F31: Furnishings & Finishes | P31: ●
D32: 4.6. Any adjacent surfaces to the sink are protected from water splashes (via splash guards or other means). | E32: Yes | F32: Furnishings & Finishes | P32: ●
D33: 4.7. Care provider furniture can easily be moved to accommodate staff and patient needs. | E33: Yes | F33: Furnishings & Finishes | P33: ● | R33: ● | T33: ● | AC33: ● | AM33: 5.2 | AN33: 5.6
D34: 4.8. There is a clearly defined zone for a patient observer, out of the way of key staff workflows. | E34: Yes | F34: Architectural Elements | I34: ● | V34: ● | AC34: ●
D35: 4.9. Patient observer furniture can easily be moved to accommodate varying needs. | E35: Yes | F35: Furnishings & Finishes | I35: ● | R35: ● | T35: ● | V35: ● | AC35: ● | AM35: 5.2 | AN35: 5.6
D36: 4.10. It is possible for a patient observer to sit within arms' length of the patient without blocking staff workflows. | E36: Yes | F36: Architectural Elements | I36: ● | V36: ● | AC36: ●
D37: 4.11. The computer workstation (either fixed or mobile) is positionable such that staff can maintain a clear line of sight to the patient while using the workstation. | E37: Yes | F37: Architectural Elements | I37: ● | V37: ●
D38: 4.12. The patient bed and/or chair can be moved in and out of the room with ease. | E38: Yes | F38: Furnishings & Finishes | P38: ● | V38: ● | AM38: 5.2 | AN38: 5.6
D39: 4.13. The room door size, type, and location supports rapid, unobstructed entry into the room and to the patient bed and/or chair. | E39: Yes | F39: Architectural Elements | I39: ● | V39: ●
D40: 4.14. The vitals monitor is positioned to be conveniently visible and unobstructed to staff | E40: Not Applicable | F40: MEP & Building Systems | R40: ● | V40: ● | W40: ●
...

Sheet DAT Report
C5: Design Alignement Tool Report
C7: Refer to the Design Guidelines chapter of the Toolkit Companion Book to learn about each of the design guidelines. This prioritization worksheet shows how important each guideline is for your project, according to related objectives and their priorities
C8: Review the importance based on outcome prioritization, then select from the options in the dropdown menu in the "Review Importance" column to either confirm or adjust the levels of importance for each guideline
C10: Category | D10: Guideline | E10: Importance | F10: Importance weighting score | G10: Total Itens | H10: Yes (Count as 1) | I10: Maybes (count as null) | J10: No's (Count as null) | K10: Maximum score | L10: Score obtained | M10: Alignement Score* (percentage, unweighted)
C11: Patient Safety | D11: 1. Maximize staff's situational awareness of the patient | E11: ='Guideline Prioritization'!O12 -> Critically Important / Essential | F11: =_xlfn.XLOOKUP(E11,'Response Options'!$D$5:$D$10,'Response Options'!$E$5:$E$10) -> 5 | G11: =COUNTIF('Design alignement tool'!E4:E9,"<>Not Applicable") -> 6 | H11: =COUNTIF('Design alignement tool'!E4:E9, "yes") -> 3 | I11: =COUNTIF('Design alignement tool'!E4:E9, "Maybe") -> 2 | J11: =COUNTIF('Design alignement tool'!E4:E9,"No") -> 1 | K11: =(G11)*F11 -> 30 | L11: =(H11*F11) -> 15 | M11: =L11/K11 -> 0.5
D12: 2. Reduce opportunities for the patient to cause harm | E12: ='Guideline Prioritization'!O13 -> Very Important | F12: =_xlfn.XLOOKUP(E12,'Response Options'!$D$5:$D$10,'Response Options'!$E$5:$E$10) -> 3 | G12: =COUNTIF('Design alignement tool'!E10:E21,"<>Not Applicable") -> 12 | H12: =COUNTIF('Design alignement tool'!E10:E21, "yes") -> 11 | I12: =COUNTIF('Design alignement tool'!E10:E21, "Maybe") -> 1 | J12: =COUNTIF('Design alignement tool'!E10:E21, "No") -> 0 | K12: =(G12)*F12 -> 36 | L12: =(H12*F12) -> 33 | M12: =L12/K12 -> 0.91666667
D13: 3. Enhance sense of security for the patient and caregiver | E13: ='Guideline Prioritization'!O14 -> Moderately Important | F13: =_xlfn.XLOOKUP(E13,'Response Options'!$D$5:$D$10,'Response Options'!$E$5:$E$10) -> 2 | G13: =COUNTIF('Design alignement tool'!E22:E26,"<>Not Applicable") -> 5 | H13: =COUNTIF('Design alignement tool'!E22:E26, "yes") -> 4 | I13: =COUNTIF('Design alignement tool'!E22:E26, "Maybe") -> 0 | J13: =COUNTIF('Design alignement tool'!E22:E26, "No") -> 1 | K13: =(G13)*F13 -> 10 | L13: =(H13*F13) -> 8 | M13: =L13/K13 -> 0.8
C14: Worker Safety & Effectiveness | D14: 4. Optimize staff workflow | E14: ='Guideline Prioritization'!O15 -> Very Important | F14: =_xlfn.XLOOKUP(E14,'Response Options'!$D$5:$D$10,'Response Options'!$E$5:$E$10) -> 3 | G14: =COUNTIF('Design alignement tool'!E27:E51,"<>Not Applicable") -> 24 | H14: =COUNTIF('Design alignement tool'!E27:E51, "yes") -> 23 | I14: =COUNTIF('Design alignement tool'!E27:E51, "Maybe") -> 1 | J14: =COUNTIF('Design alignement tool'!E27:E51, "No") -> 0 | K14: =(G14)*F14 -> 72 | L14: =(H14*F14) -> 69 | M14: =L14/K14 -> 0.95833333
D15: 5. Improve safety and security for staff | E15: ='Guideline Prioritization'!O16 -> Slightly important | F15: =_xlfn.XLOOKUP(E15,'Response Options'!$D$5:$D$10,'Response Options'!$E$5:$E$10) -> 1 | G15: =COUNTIF('Design alignement tool'!E52:E57,"<>Not Applicable") -> 6 | H15: =COUNTIF('Design alignement tool'!E52:E57, "yes") -> 5 | I15: =COUNTIF('Design alignement tool'!E52:E57, "Maybe") -> 0 | J15: =COUNTIF('Design alignement tool'!E52:E57, "No") -> 1 | K15: =(G15)*F15 -> 6 | L15: =(H15*F15) -> 5 | M15: =L15/K15 -> 0.83333333
D16: 6. Provide flexible and adaptable work environments | E16: ='Guideline Prioritization'!O17 -> Moderately Important | F16: =_xlfn.XLOOKUP(E16,'Response Options'!$D$5:$D$10,'Response Options'!$E$5:$E$10) -> 2 | G16: =COUNTIF('Design alignement tool'!E58:E67,"<>Not Applicable") -> 9 | H16: =COUNTIF('Design alignement tool'!E58:E67, "yes") -> 8 | I16: =COUNTIF('Design alignement tool'!E58:E67, "Maybe") -> 0 | J16: =COUNTIF('Design alignement tool'!E58:E67, "No") -> 1 | K16: =(G16)*F16 -> 18 | L16: =(H16*F16) -> 16 | M16: =L16/K16 -> 0.88888889
C17: Patient Care Quality & Experience | D17: 9. Provide opportunities for engaging patients and care partners | E17: ='Guideline Prioritization'!O20 -> Slightly important | F17: =_xlfn.XLOOKUP(E17,'Response Options'!$D$5:$D$10,'Response Options'!$E$5:$E$10) -> 1 | G17: =COUNTIF('Design alignement tool'!E68:E75,"<>Not Applicable") -> 8 | H17: =COUNTIF('Design alignement tool'!E68:E75, "yes") -> 7 | I17: =COUNTIF('Design alignement tool'!E68:E75, "Maybe") -> 0 | J17: =COUNTIF('Design alignement tool'!E68:E75, "No") -> 1 | K17: =(G17)*F17 -> 8 | L17: =(H17*F17) -> 7 | M17: =L17/K17 -> 0.875
D18: 10. Support patient and family dignity and comfort | E18: ='Guideline Prioritization'!O21 -> Very Important | F18: =_xlfn.XLOOKUP(E18,'Response Options'!$D$5:$D$10,'Response Options'!$E$5:$E$10) -> 3 | G18: =COUNTIF('Design alignement tool'!E76:E92,"<>Not Applicable") -> 17 | H18: =COUNTIF('Design alignement tool'!E76:E92, "yes") -> 16 | I18: =COUNTIF('Design alignement tool'!E76:E92, "Maybe") -> 0 | J18: =COUNTIF('Design alignement tool'!E76:E92, "No") -> 1 | K18: =(G18)*F18 -> 51 | L18: =(H18*F18) -> 48 | M18: =L18/K18 -> 0.94117647
D19: 11. Create opportunities for auditory and visual privacy | E19: ='Guideline Prioritization'!O22 -> Critically Important / Essential | F19: =_xlfn.XLOOKUP(E19,'Response Options'!$D$5:$D$10,'Response Options'!$E$5:$E$10) -> 5 | G19: =COUNTIF('Design alignement tool'!E93:E96,"<>Not Applicable") -> 4 | H19: =COUNTIF('Design alignement tool'!E93:E96, "yes") -> 3 | I19: =COUNTIF('Design alignement tool'!E93:E96, "Maybe") -> 0 | J19: =COUNTIF('Design alignement tool'!E76:E92, "No") -> 1 | K19: =(G19)*F19 -> 20 | L19: =(H19*F19) -> 15 | M19: =L19/K19 -> 0.75
D20: 12. Provide patient choice and control over the environment | E20: ='Guideline Prioritization'!O23 -> Moderately Important | F20: =_xlfn.XLOOKUP(E20,'Response Options'!$D$5:$D$10,'Response Options'!$E$5:$E$10) -> 2 | G20: =COUNTIF('Design alignement tool'!E97:E103,"<>Not Applicable") -> 7 | H20: =COUNTIF('Design alignement tool'!E97:E103, "yes") -> 7 | I20: =COUNTIF('Design alignement tool'!E97:E103, "Maybe") -> 0 | J20: =COUNTIF('Design alignement tool'!E97:E103, "No") -> 0 | K20: =(G20)*F20 -> 14 | L20: =(H20*F20) -> 14 | M20: =L20/K20 -> 1
D21: 13. Create opportunities for sensory-friendly support | E21: ='Guideline Prioritization'!O24 -> Moderately Important | F21: =_xlfn.XLOOKUP(E21,'Response Options'!$D$5:$D$10,'Response Options'!$E$5:$E$10) -> 2 | G21: =COUNTIF('Design alignement tool'!E104:E108,"<>Not Applicable") -> 5 | H21: =COUNTIF('Design alignement tool'!E104:E108, "yes") -> 3 | I21: =COUNTIF('Design alignement tool'!E104:E108, "Maybe") -> 0 | J21: =COUNTIF('Design alignement tool'!E104:E108, "No") -> 2 | K21: =(G21)*F21 -> 10 | L21: =(H21*F21) -> 6 | M21: =L21/K21 -> 0.6
C22: Organizational Performance | D22: 14.Support clarity and anticipation of the care path and steps in the healthcare experience. | E22: ='Guideline Prioritization'!O25 -> Moderately Important | F22: =_xlfn.XLOOKUP(E22,'Response Options'!$D$5:$D$10,'Response Options'!$E$5:$E$10) -> 2 | K22: =(G22-I22)*F22 -> 0
D23: 15. Provide timely access to psychiatric care | E23: ='Guideline Prioritization'!O26 -> Critically Important / Essential | F23: =_xlfn.XLOOKUP(E23,'Response Options'!$D$5:$D$10,'Response Options'!$E$5:$E$10) -> 5 | K23: =(G23-I23)*F23 -> 0

Sheet Response Options
A2: Pre-planning & Programming Worksheet | D2: Outcome-Guideline Prioritization | H2: Design alignement tool
F3: guideline
A4: 3 | B4: Renovation | D4: PT Importance Scoring | H4: PT Importance Scoring
B5: New Construction | D5: Critically Important / Essential | E5: 5 | F5: 6 | H5: Yes | I5: 1
D6: Extremely Important | E6: 4 | F6: 5 | H6: No | I6: -1
